{
 "cells": [
  {
   "cell_type": "code",
   "execution_count": 1,
   "id": "e7151d0d",
   "metadata": {},
   "outputs": [],
   "source": [
    "# 1. 케라스로 구현하는 로지스틱 회귀"
   ]
  },
  {
   "cell_type": "code",
   "execution_count": 2,
   "id": "98f004b9",
   "metadata": {},
   "outputs": [
    {
     "name": "stdout",
     "output_type": "stream",
     "text": [
      "Epoch 1/100\n"
     ]
    },
    {
     "name": "stderr",
     "output_type": "stream",
     "text": [
      "/usr/local/lib/python3.8/dist-packages/keras/optimizers/optimizer_v2/gradient_descent.py:111: UserWarning: The `lr` argument is deprecated, use `learning_rate` instead.\n",
      "  super().__init__(name, **kwargs)\n"
     ]
    },
    {
     "ename": "InternalError",
     "evalue": "Graph execution error:\n\nDetected at node 'sequential_1/dense/MatMul' defined at (most recent call last):\n    File \"/usr/lib/python3.8/runpy.py\", line 194, in _run_module_as_main\n      return _run_code(code, main_globals, None,\n    File \"/usr/lib/python3.8/runpy.py\", line 87, in _run_code\n      exec(code, run_globals)\n    File \"/usr/lib/python3/dist-packages/ipykernel_launcher.py\", line 16, in <module>\n      app.launch_new_instance()\n    File \"/home/hyuntak/.local/lib/python3.8/site-packages/traitlets/config/application.py\", line 978, in launch_instance\n      app.start()\n    File \"/usr/lib/python3/dist-packages/ipykernel/kernelapp.py\", line 583, in start\n      self.io_loop.start()\n    File \"/home/hyuntak/.local/lib/python3.8/site-packages/tornado/platform/asyncio.py\", line 215, in start\n      self.asyncio_loop.run_forever()\n    File \"/usr/lib/python3.8/asyncio/base_events.py\", line 570, in run_forever\n      self._run_once()\n    File \"/usr/lib/python3.8/asyncio/base_events.py\", line 1859, in _run_once\n      handle._run()\n    File \"/usr/lib/python3.8/asyncio/events.py\", line 81, in _run\n      self._context.run(self._callback, *self._args)\n    File \"/home/hyuntak/.local/lib/python3.8/site-packages/tornado/ioloop.py\", line 687, in <lambda>\n      lambda f: self._run_callback(functools.partial(callback, future))\n    File \"/home/hyuntak/.local/lib/python3.8/site-packages/tornado/ioloop.py\", line 740, in _run_callback\n      ret = callback()\n    File \"/home/hyuntak/.local/lib/python3.8/site-packages/tornado/gen.py\", line 821, in inner\n      self.ctx_run(self.run)\n    File \"/home/hyuntak/.local/lib/python3.8/site-packages/tornado/gen.py\", line 782, in run\n      yielded = self.gen.send(value)\n    File \"/usr/lib/python3/dist-packages/ipykernel/kernelbase.py\", line 365, in process_one\n      yield gen.maybe_future(dispatch(*args))\n    File \"/home/hyuntak/.local/lib/python3.8/site-packages/tornado/gen.py\", line 234, in wrapper\n      yielded = ctx_run(next, result)\n    File \"/usr/lib/python3/dist-packages/ipykernel/kernelbase.py\", line 268, in dispatch_shell\n      yield gen.maybe_future(handler(stream, idents, msg))\n    File \"/home/hyuntak/.local/lib/python3.8/site-packages/tornado/gen.py\", line 234, in wrapper\n      yielded = ctx_run(next, result)\n    File \"/usr/lib/python3/dist-packages/ipykernel/kernelbase.py\", line 543, in execute_request\n      self.do_execute(\n    File \"/home/hyuntak/.local/lib/python3.8/site-packages/tornado/gen.py\", line 234, in wrapper\n      yielded = ctx_run(next, result)\n    File \"/usr/lib/python3/dist-packages/ipykernel/ipkernel.py\", line 300, in do_execute\n      res = shell.run_cell(code, store_history=store_history, silent=silent)\n    File \"/usr/lib/python3/dist-packages/ipykernel/zmqshell.py\", line 536, in run_cell\n      return super(ZMQInteractiveShell, self).run_cell(*args, **kwargs)\n    File \"/usr/lib/python3/dist-packages/IPython/core/interactiveshell.py\", line 2857, in run_cell\n      result = self._run_cell(\n    File \"/usr/lib/python3/dist-packages/IPython/core/interactiveshell.py\", line 2886, in _run_cell\n      return runner(coro)\n    File \"/usr/lib/python3/dist-packages/IPython/core/async_helpers.py\", line 68, in _pseudo_sync_runner\n      coro.send(None)\n    File \"/usr/lib/python3/dist-packages/IPython/core/interactiveshell.py\", line 3062, in run_cell_async\n      has_raised = await self.run_ast_nodes(code_ast.body, cell_name,\n    File \"/usr/lib/python3/dist-packages/IPython/core/interactiveshell.py\", line 3254, in run_ast_nodes\n      if (await self.run_code(code, result,  async_=asy)):\n    File \"/usr/lib/python3/dist-packages/IPython/core/interactiveshell.py\", line 3331, in run_code\n      exec(code_obj, self.user_global_ns, self.user_ns)\n    File \"<ipython-input-2-c8539229fc08>\", line 21, in <module>\n      model.fit(x, y, epochs=100)\n    File \"/usr/local/lib/python3.8/dist-packages/keras/utils/traceback_utils.py\", line 65, in error_handler\n      return fn(*args, **kwargs)\n    File \"/usr/local/lib/python3.8/dist-packages/keras/engine/training.py\", line 1564, in fit\n      tmp_logs = self.train_function(iterator)\n    File \"/usr/local/lib/python3.8/dist-packages/keras/engine/training.py\", line 1160, in train_function\n      return step_function(self, iterator)\n    File \"/usr/local/lib/python3.8/dist-packages/keras/engine/training.py\", line 1146, in step_function\n      outputs = model.distribute_strategy.run(run_step, args=(data,))\n    File \"/usr/local/lib/python3.8/dist-packages/keras/engine/training.py\", line 1135, in run_step\n      outputs = model.train_step(data)\n    File \"/usr/local/lib/python3.8/dist-packages/keras/engine/training.py\", line 993, in train_step\n      y_pred = self(x, training=True)\n    File \"/usr/local/lib/python3.8/dist-packages/keras/utils/traceback_utils.py\", line 65, in error_handler\n      return fn(*args, **kwargs)\n    File \"/usr/local/lib/python3.8/dist-packages/keras/engine/training.py\", line 557, in __call__\n      return super().__call__(*args, **kwargs)\n    File \"/usr/local/lib/python3.8/dist-packages/keras/utils/traceback_utils.py\", line 65, in error_handler\n      return fn(*args, **kwargs)\n    File \"/usr/local/lib/python3.8/dist-packages/keras/engine/base_layer.py\", line 1097, in __call__\n      outputs = call_fn(inputs, *args, **kwargs)\n    File \"/usr/local/lib/python3.8/dist-packages/keras/utils/traceback_utils.py\", line 96, in error_handler\n      return fn(*args, **kwargs)\n    File \"/usr/local/lib/python3.8/dist-packages/keras/engine/sequential.py\", line 410, in call\n      return super().call(inputs, training=training, mask=mask)\n    File \"/usr/local/lib/python3.8/dist-packages/keras/engine/functional.py\", line 510, in call\n      return self._run_internal_graph(inputs, training=training, mask=mask)\n    File \"/usr/local/lib/python3.8/dist-packages/keras/engine/functional.py\", line 667, in _run_internal_graph\n      outputs = node.layer(*args, **kwargs)\n    File \"/usr/local/lib/python3.8/dist-packages/keras/utils/traceback_utils.py\", line 65, in error_handler\n      return fn(*args, **kwargs)\n    File \"/usr/local/lib/python3.8/dist-packages/keras/engine/base_layer.py\", line 1097, in __call__\n      outputs = call_fn(inputs, *args, **kwargs)\n    File \"/usr/local/lib/python3.8/dist-packages/keras/utils/traceback_utils.py\", line 96, in error_handler\n      return fn(*args, **kwargs)\n    File \"/usr/local/lib/python3.8/dist-packages/keras/layers/core/dense.py\", line 241, in call\n      outputs = tf.matmul(a=inputs, b=self.kernel)\nNode: 'sequential_1/dense/MatMul'\nBlas xGEMV launch failed : a.shape=[1,13,1], b.shape=[1,1,1], m=13, n=1, k=1\n\t [[{{node sequential_1/dense/MatMul}}]] [Op:__inference_train_function_542]",
     "output_type": "error",
     "traceback": [
      "\u001b[0;31m---------------------------------------------------------------------------\u001b[0m",
      "\u001b[0;31mInternalError\u001b[0m                             Traceback (most recent call last)",
      "\u001b[0;32m<ipython-input-2-c8539229fc08>\u001b[0m in \u001b[0;36m<module>\u001b[0;34m\u001b[0m\n\u001b[1;32m     19\u001b[0m \u001b[0mmodel\u001b[0m\u001b[0;34m.\u001b[0m\u001b[0mcompile\u001b[0m\u001b[0;34m(\u001b[0m\u001b[0moptimizer\u001b[0m\u001b[0;34m=\u001b[0m\u001b[0msgd\u001b[0m\u001b[0;34m,\u001b[0m \u001b[0mloss\u001b[0m\u001b[0;34m=\u001b[0m\u001b[0;34m'binary_crossentropy'\u001b[0m\u001b[0;34m,\u001b[0m \u001b[0mmetrics\u001b[0m\u001b[0;34m=\u001b[0m\u001b[0;34m[\u001b[0m\u001b[0;34m'binary_accuracy'\u001b[0m\u001b[0;34m]\u001b[0m\u001b[0;34m)\u001b[0m\u001b[0;34m\u001b[0m\u001b[0;34m\u001b[0m\u001b[0m\n\u001b[1;32m     20\u001b[0m \u001b[0;34m\u001b[0m\u001b[0m\n\u001b[0;32m---> 21\u001b[0;31m \u001b[0mmodel\u001b[0m\u001b[0;34m.\u001b[0m\u001b[0mfit\u001b[0m\u001b[0;34m(\u001b[0m\u001b[0mx\u001b[0m\u001b[0;34m,\u001b[0m \u001b[0my\u001b[0m\u001b[0;34m,\u001b[0m \u001b[0mepochs\u001b[0m\u001b[0;34m=\u001b[0m\u001b[0;36m100\u001b[0m\u001b[0;34m)\u001b[0m\u001b[0;34m\u001b[0m\u001b[0;34m\u001b[0m\u001b[0m\n\u001b[0m",
      "\u001b[0;32m/usr/local/lib/python3.8/dist-packages/keras/utils/traceback_utils.py\u001b[0m in \u001b[0;36merror_handler\u001b[0;34m(*args, **kwargs)\u001b[0m\n\u001b[1;32m     68\u001b[0m             \u001b[0;31m# To get the full stack trace, call:\u001b[0m\u001b[0;34m\u001b[0m\u001b[0;34m\u001b[0m\u001b[0;34m\u001b[0m\u001b[0m\n\u001b[1;32m     69\u001b[0m             \u001b[0;31m# `tf.debugging.disable_traceback_filtering()`\u001b[0m\u001b[0;34m\u001b[0m\u001b[0;34m\u001b[0m\u001b[0;34m\u001b[0m\u001b[0m\n\u001b[0;32m---> 70\u001b[0;31m             \u001b[0;32mraise\u001b[0m \u001b[0me\u001b[0m\u001b[0;34m.\u001b[0m\u001b[0mwith_traceback\u001b[0m\u001b[0;34m(\u001b[0m\u001b[0mfiltered_tb\u001b[0m\u001b[0;34m)\u001b[0m \u001b[0;32mfrom\u001b[0m \u001b[0;32mNone\u001b[0m\u001b[0;34m\u001b[0m\u001b[0;34m\u001b[0m\u001b[0m\n\u001b[0m\u001b[1;32m     71\u001b[0m         \u001b[0;32mfinally\u001b[0m\u001b[0;34m:\u001b[0m\u001b[0;34m\u001b[0m\u001b[0;34m\u001b[0m\u001b[0m\n\u001b[1;32m     72\u001b[0m             \u001b[0;32mdel\u001b[0m \u001b[0mfiltered_tb\u001b[0m\u001b[0;34m\u001b[0m\u001b[0;34m\u001b[0m\u001b[0m\n",
      "\u001b[0;32m/usr/local/lib/python3.8/dist-packages/tensorflow/python/eager/execute.py\u001b[0m in \u001b[0;36mquick_execute\u001b[0;34m(op_name, num_outputs, inputs, attrs, ctx, name)\u001b[0m\n\u001b[1;32m     52\u001b[0m   \u001b[0;32mtry\u001b[0m\u001b[0;34m:\u001b[0m\u001b[0;34m\u001b[0m\u001b[0;34m\u001b[0m\u001b[0m\n\u001b[1;32m     53\u001b[0m     \u001b[0mctx\u001b[0m\u001b[0;34m.\u001b[0m\u001b[0mensure_initialized\u001b[0m\u001b[0;34m(\u001b[0m\u001b[0;34m)\u001b[0m\u001b[0;34m\u001b[0m\u001b[0;34m\u001b[0m\u001b[0m\n\u001b[0;32m---> 54\u001b[0;31m     tensors = pywrap_tfe.TFE_Py_Execute(ctx._handle, device_name, op_name,\n\u001b[0m\u001b[1;32m     55\u001b[0m                                         inputs, attrs, num_outputs)\n\u001b[1;32m     56\u001b[0m   \u001b[0;32mexcept\u001b[0m \u001b[0mcore\u001b[0m\u001b[0;34m.\u001b[0m\u001b[0m_NotOkStatusException\u001b[0m \u001b[0;32mas\u001b[0m \u001b[0me\u001b[0m\u001b[0;34m:\u001b[0m\u001b[0;34m\u001b[0m\u001b[0;34m\u001b[0m\u001b[0m\n",
      "\u001b[0;31mInternalError\u001b[0m: Graph execution error:\n\nDetected at node 'sequential_1/dense/MatMul' defined at (most recent call last):\n    File \"/usr/lib/python3.8/runpy.py\", line 194, in _run_module_as_main\n      return _run_code(code, main_globals, None,\n    File \"/usr/lib/python3.8/runpy.py\", line 87, in _run_code\n      exec(code, run_globals)\n    File \"/usr/lib/python3/dist-packages/ipykernel_launcher.py\", line 16, in <module>\n      app.launch_new_instance()\n    File \"/home/hyuntak/.local/lib/python3.8/site-packages/traitlets/config/application.py\", line 978, in launch_instance\n      app.start()\n    File \"/usr/lib/python3/dist-packages/ipykernel/kernelapp.py\", line 583, in start\n      self.io_loop.start()\n    File \"/home/hyuntak/.local/lib/python3.8/site-packages/tornado/platform/asyncio.py\", line 215, in start\n      self.asyncio_loop.run_forever()\n    File \"/usr/lib/python3.8/asyncio/base_events.py\", line 570, in run_forever\n      self._run_once()\n    File \"/usr/lib/python3.8/asyncio/base_events.py\", line 1859, in _run_once\n      handle._run()\n    File \"/usr/lib/python3.8/asyncio/events.py\", line 81, in _run\n      self._context.run(self._callback, *self._args)\n    File \"/home/hyuntak/.local/lib/python3.8/site-packages/tornado/ioloop.py\", line 687, in <lambda>\n      lambda f: self._run_callback(functools.partial(callback, future))\n    File \"/home/hyuntak/.local/lib/python3.8/site-packages/tornado/ioloop.py\", line 740, in _run_callback\n      ret = callback()\n    File \"/home/hyuntak/.local/lib/python3.8/site-packages/tornado/gen.py\", line 821, in inner\n      self.ctx_run(self.run)\n    File \"/home/hyuntak/.local/lib/python3.8/site-packages/tornado/gen.py\", line 782, in run\n      yielded = self.gen.send(value)\n    File \"/usr/lib/python3/dist-packages/ipykernel/kernelbase.py\", line 365, in process_one\n      yield gen.maybe_future(dispatch(*args))\n    File \"/home/hyuntak/.local/lib/python3.8/site-packages/tornado/gen.py\", line 234, in wrapper\n      yielded = ctx_run(next, result)\n    File \"/usr/lib/python3/dist-packages/ipykernel/kernelbase.py\", line 268, in dispatch_shell\n      yield gen.maybe_future(handler(stream, idents, msg))\n    File \"/home/hyuntak/.local/lib/python3.8/site-packages/tornado/gen.py\", line 234, in wrapper\n      yielded = ctx_run(next, result)\n    File \"/usr/lib/python3/dist-packages/ipykernel/kernelbase.py\", line 543, in execute_request\n      self.do_execute(\n    File \"/home/hyuntak/.local/lib/python3.8/site-packages/tornado/gen.py\", line 234, in wrapper\n      yielded = ctx_run(next, result)\n    File \"/usr/lib/python3/dist-packages/ipykernel/ipkernel.py\", line 300, in do_execute\n      res = shell.run_cell(code, store_history=store_history, silent=silent)\n    File \"/usr/lib/python3/dist-packages/ipykernel/zmqshell.py\", line 536, in run_cell\n      return super(ZMQInteractiveShell, self).run_cell(*args, **kwargs)\n    File \"/usr/lib/python3/dist-packages/IPython/core/interactiveshell.py\", line 2857, in run_cell\n      result = self._run_cell(\n    File \"/usr/lib/python3/dist-packages/IPython/core/interactiveshell.py\", line 2886, in _run_cell\n      return runner(coro)\n    File \"/usr/lib/python3/dist-packages/IPython/core/async_helpers.py\", line 68, in _pseudo_sync_runner\n      coro.send(None)\n    File \"/usr/lib/python3/dist-packages/IPython/core/interactiveshell.py\", line 3062, in run_cell_async\n      has_raised = await self.run_ast_nodes(code_ast.body, cell_name,\n    File \"/usr/lib/python3/dist-packages/IPython/core/interactiveshell.py\", line 3254, in run_ast_nodes\n      if (await self.run_code(code, result,  async_=asy)):\n    File \"/usr/lib/python3/dist-packages/IPython/core/interactiveshell.py\", line 3331, in run_code\n      exec(code_obj, self.user_global_ns, self.user_ns)\n    File \"<ipython-input-2-c8539229fc08>\", line 21, in <module>\n      model.fit(x, y, epochs=100)\n    File \"/usr/local/lib/python3.8/dist-packages/keras/utils/traceback_utils.py\", line 65, in error_handler\n      return fn(*args, **kwargs)\n    File \"/usr/local/lib/python3.8/dist-packages/keras/engine/training.py\", line 1564, in fit\n      tmp_logs = self.train_function(iterator)\n    File \"/usr/local/lib/python3.8/dist-packages/keras/engine/training.py\", line 1160, in train_function\n      return step_function(self, iterator)\n    File \"/usr/local/lib/python3.8/dist-packages/keras/engine/training.py\", line 1146, in step_function\n      outputs = model.distribute_strategy.run(run_step, args=(data,))\n    File \"/usr/local/lib/python3.8/dist-packages/keras/engine/training.py\", line 1135, in run_step\n      outputs = model.train_step(data)\n    File \"/usr/local/lib/python3.8/dist-packages/keras/engine/training.py\", line 993, in train_step\n      y_pred = self(x, training=True)\n    File \"/usr/local/lib/python3.8/dist-packages/keras/utils/traceback_utils.py\", line 65, in error_handler\n      return fn(*args, **kwargs)\n    File \"/usr/local/lib/python3.8/dist-packages/keras/engine/training.py\", line 557, in __call__\n      return super().__call__(*args, **kwargs)\n    File \"/usr/local/lib/python3.8/dist-packages/keras/utils/traceback_utils.py\", line 65, in error_handler\n      return fn(*args, **kwargs)\n    File \"/usr/local/lib/python3.8/dist-packages/keras/engine/base_layer.py\", line 1097, in __call__\n      outputs = call_fn(inputs, *args, **kwargs)\n    File \"/usr/local/lib/python3.8/dist-packages/keras/utils/traceback_utils.py\", line 96, in error_handler\n      return fn(*args, **kwargs)\n    File \"/usr/local/lib/python3.8/dist-packages/keras/engine/sequential.py\", line 410, in call\n      return super().call(inputs, training=training, mask=mask)\n    File \"/usr/local/lib/python3.8/dist-packages/keras/engine/functional.py\", line 510, in call\n      return self._run_internal_graph(inputs, training=training, mask=mask)\n    File \"/usr/local/lib/python3.8/dist-packages/keras/engine/functional.py\", line 667, in _run_internal_graph\n      outputs = node.layer(*args, **kwargs)\n    File \"/usr/local/lib/python3.8/dist-packages/keras/utils/traceback_utils.py\", line 65, in error_handler\n      return fn(*args, **kwargs)\n    File \"/usr/local/lib/python3.8/dist-packages/keras/engine/base_layer.py\", line 1097, in __call__\n      outputs = call_fn(inputs, *args, **kwargs)\n    File \"/usr/local/lib/python3.8/dist-packages/keras/utils/traceback_utils.py\", line 96, in error_handler\n      return fn(*args, **kwargs)\n    File \"/usr/local/lib/python3.8/dist-packages/keras/layers/core/dense.py\", line 241, in call\n      outputs = tf.matmul(a=inputs, b=self.kernel)\nNode: 'sequential_1/dense/MatMul'\nBlas xGEMV launch failed : a.shape=[1,13,1], b.shape=[1,1,1], m=13, n=1, k=1\n\t [[{{node sequential_1/dense/MatMul}}]] [Op:__inference_train_function_542]"
     ]
    }
   ],
   "source": [
    "import numpy as np\n",
    "import matplotlib.pyplot as plt\n",
    "from tensorflow.keras.models import Sequential\n",
    "from tensorflow.keras.layers import Dense\n",
    "from tensorflow.keras import optimizers\n",
    "\n",
    "x = [-50, -40, -30, -20, -10, -5, 0, 5, 10, 20, 30, 40, 50]\n",
    "y = [0, 0, 0, 0, 0, 0, 0, 0, 1, 1, 1, 1, 1] # 숫자 10부터 1\n",
    "\n",
    "model = Sequential()\n",
    "\n",
    "\n",
    "model.add(Dense(1, input_dim=1, activation='sigmoid'))\n",
    "\n",
    "sgd = optimizers.SGD(lr=0.01)\n",
    "\n",
    "# 로지스틱 회귀는 사실 회귀가아닌 분류문제이므로 cross entropy를 loss function으로 사용한다.\n",
    "\n",
    "model.compile(optimizer=sgd, loss='binary_crossentropy', metrics=['binary_accuracy'])\n",
    "\n",
    "model.fit(x, y, epochs=300)\n",
    "\n",
    "# 에러의 원인을 모르겠다."
   ]
  },
  {
   "cell_type": "code",
   "execution_count": null,
   "id": "ec700481",
   "metadata": {},
   "outputs": [],
   "source": []
  },
  {
   "cell_type": "code",
   "execution_count": null,
   "id": "d9b6a8fa",
   "metadata": {},
   "outputs": [],
   "source": []
  }
 ],
 "metadata": {
  "kernelspec": {
   "display_name": "Python 3",
   "language": "python",
   "name": "python3"
  },
  "language_info": {
   "codemirror_mode": {
    "name": "ipython",
    "version": 3
   },
   "file_extension": ".py",
   "mimetype": "text/x-python",
   "name": "python",
   "nbconvert_exporter": "python",
   "pygments_lexer": "ipython3",
   "version": "3.8.10"
  }
 },
 "nbformat": 4,
 "nbformat_minor": 5
}
